INFO 2018-09-14 17:25:28,556 basehttp 124 "GET / HTTP/1.1" 200 1714
INFO 2018-09-17 19:27:23,234 basehttp 124 "GET / HTTP/1.1" 200 1714
ERROR 2018-09-17 19:27:44,484 exception 80 Invalid HTTP_HOST header: 'api.meiduo.site:8000'. You may need to add 'api.meiduo.site' to ALLOWED_HOSTS.
WARNING 2018-09-17 19:27:44,670 basehttp 124 "GET / HTTP/1.1" 400 72461
ERROR 2018-09-18 19:24:42,819 exception 80 Invalid HTTP_HOST header: 'www.meiduo.site:8000'. You may need to add 'www.meiduo.site' to ALLOWED_HOSTS.
WARNING 2018-09-18 19:24:42,992 basehttp 124 "GET / HTTP/1.1" 400 73229
ERROR 2018-09-18 19:24:43,128 exception 80 Invalid HTTP_HOST header: 'www.meiduo.site:8000'. You may need to add 'www.meiduo.site' to ALLOWED_HOSTS.
WARNING 2018-09-18 19:24:43,188 basehttp 124 "GET /favicon.ico HTTP/1.1" 400 73313
ERROR 2018-09-18 19:25:59,965 exception 80 Invalid HTTP_HOST header: 'www.meiduo.site:8000'. You may need to add 'www.meiduo.site' to ALLOWED_HOSTS.
WARNING 2018-09-18 19:26:00,033 basehttp 124 "GET / HTTP/1.1" 400 73364
ERROR 2018-09-18 19:26:00,191 exception 80 Invalid HTTP_HOST header: 'www.meiduo.site:8000'. You may need to add 'www.meiduo.site' to ALLOWED_HOSTS.
WARNING 2018-09-18 19:26:00,251 basehttp 124 "GET /favicon.ico HTTP/1.1" 400 73574
INFO 2018-09-18 19:27:58,642 basehttp 124 "GET / HTTP/1.1" 200 1714
WARNING 2018-09-18 19:28:06,389 base 152 Not Found: /SMSCodesView/
WARNING 2018-09-18 19:28:06,390 basehttp 124 "GET /SMSCodesView/ HTTP/1.1" 404 1979
ERROR 2018-09-18 19:34:41,453 exceptions 25 [<verifications.views.SMSCodesView object at 0x7f1e151d9518>] Error 101 connecting to 10.211.55.5:6379. Network is unreachable.
ERROR 2018-09-18 19:34:41,454 basehttp 124 "GET /sms_code/13955660980/ HTTP/1.1" 507 35
ERROR 2018-09-18 19:35:34,248 exceptions 25 [<verifications.views.SMSCodesView object at 0x7f1e10d981d0>] Error 101 connecting to 10.211.55.5:6379. Network is unreachable.
ERROR 2018-09-18 19:35:34,250 basehttp 124 "GET /sms_code/13955660980/ HTTP/1.1" 507 35
ERROR 2018-09-18 19:36:05,706 exceptions 25 [<verifications.views.SMSCodesView object at 0x7faa524649b0>] Error 101 connecting to 10.211.55.5:6379. Network is unreachable.
ERROR 2018-09-18 19:36:05,707 basehttp 124 "GET /sms_code/13955660980/ HTTP/1.1" 507 35
INFO 2018-09-18 19:41:47,245 views 30 短信验证码为: 901888
ERROR 2018-09-18 19:41:47,246 exception 135 Internal Server Error: /sms_code/13955660980/
Traceback (most recent call last):
  File "/home/elvira/.virtualenvs/django_py3/lib/python3.5/site-packages/django/core/handlers/exception.py", line 41, in inner
    response = get_response(request)
  File "/home/elvira/.virtualenvs/django_py3/lib/python3.5/site-packages/django/core/handlers/base.py", line 187, in _get_response
    response = self.process_exception_by_middleware(e, request)
  File "/home/elvira/.virtualenvs/django_py3/lib/python3.5/site-packages/django/core/handlers/base.py", line 185, in _get_response
    response = wrapped_callback(request, *callback_args, **callback_kwargs)
  File "/home/elvira/.virtualenvs/django_py3/lib/python3.5/site-packages/django/views/decorators/csrf.py", line 58, in wrapped_view
    return view_func(*args, **kwargs)
  File "/home/elvira/.virtualenvs/django_py3/lib/python3.5/site-packages/django/views/generic/base.py", line 68, in view
    return self.dispatch(request, *args, **kwargs)
  File "/home/elvira/.virtualenvs/django_py3/lib/python3.5/site-packages/rest_framework/views.py", line 483, in dispatch
    response = self.handle_exception(exc)
  File "/home/elvira/.virtualenvs/django_py3/lib/python3.5/site-packages/rest_framework/views.py", line 443, in handle_exception
    self.raise_uncaught_exception(exc)
  File "/home/elvira/.virtualenvs/django_py3/lib/python3.5/site-packages/rest_framework/views.py", line 480, in dispatch
    response = handler(request, *args, **kwargs)
  File "/home/elvira/桌面/reposities/meiduo/meiduo/meiduo_mall/meiduo_mall/apps/verifications/views.py", line 32, in get
    pl = redis_conn.pipline()
AttributeError: 'StrictRedis' object has no attribute 'pipline'
ERROR 2018-09-18 19:41:47,350 basehttp 124 "GET /sms_code/13955660980/ HTTP/1.1" 500 19302
INFO 2018-09-18 19:42:50,567 views 30 短信验证码为: 555414
ERROR 2018-09-18 19:42:50,570 exception 135 Internal Server Error: /sms_code/13955660980/
Traceback (most recent call last):
  File "/home/elvira/.virtualenvs/django_py3/lib/python3.5/site-packages/django/core/handlers/exception.py", line 41, in inner
    response = get_response(request)
  File "/home/elvira/.virtualenvs/django_py3/lib/python3.5/site-packages/django/core/handlers/base.py", line 187, in _get_response
    response = self.process_exception_by_middleware(e, request)
  File "/home/elvira/.virtualenvs/django_py3/lib/python3.5/site-packages/django/core/handlers/base.py", line 185, in _get_response
    response = wrapped_callback(request, *callback_args, **callback_kwargs)
  File "/home/elvira/.virtualenvs/django_py3/lib/python3.5/site-packages/django/views/decorators/csrf.py", line 58, in wrapped_view
    return view_func(*args, **kwargs)
  File "/home/elvira/.virtualenvs/django_py3/lib/python3.5/site-packages/django/views/generic/base.py", line 68, in view
    return self.dispatch(request, *args, **kwargs)
  File "/home/elvira/.virtualenvs/django_py3/lib/python3.5/site-packages/rest_framework/views.py", line 483, in dispatch
    response = self.handle_exception(exc)
  File "/home/elvira/.virtualenvs/django_py3/lib/python3.5/site-packages/rest_framework/views.py", line 443, in handle_exception
    self.raise_uncaught_exception(exc)
  File "/home/elvira/.virtualenvs/django_py3/lib/python3.5/site-packages/rest_framework/views.py", line 480, in dispatch
    response = handler(request, *args, **kwargs)
  File "/home/elvira/桌面/reposities/meiduo/meiduo/meiduo_mall/meiduo_mall/apps/verifications/views.py", line 35, in get
    pl.setx('sms_%s' % mobile, constant.SMS_CODE_REDIS_EXPIRES, sms_code)
AttributeError: 'StrictPipeline' object has no attribute 'setx'
ERROR 2018-09-18 19:42:50,607 basehttp 124 "GET /sms_code/13955660980/ HTTP/1.1" 500 19346
INFO 2018-09-18 19:43:15,385 views 30 短信验证码为: 672770
ERROR 2018-09-18 19:43:15,386 exception 135 Internal Server Error: /sms_code/13955660980/
Traceback (most recent call last):
  File "/home/elvira/.virtualenvs/django_py3/lib/python3.5/site-packages/django/core/handlers/exception.py", line 41, in inner
    response = get_response(request)
  File "/home/elvira/.virtualenvs/django_py3/lib/python3.5/site-packages/django/core/handlers/base.py", line 187, in _get_response
    response = self.process_exception_by_middleware(e, request)
  File "/home/elvira/.virtualenvs/django_py3/lib/python3.5/site-packages/django/core/handlers/base.py", line 185, in _get_response
    response = wrapped_callback(request, *callback_args, **callback_kwargs)
  File "/home/elvira/.virtualenvs/django_py3/lib/python3.5/site-packages/django/views/decorators/csrf.py", line 58, in wrapped_view
    return view_func(*args, **kwargs)
  File "/home/elvira/.virtualenvs/django_py3/lib/python3.5/site-packages/django/views/generic/base.py", line 68, in view
    return self.dispatch(request, *args, **kwargs)
  File "/home/elvira/.virtualenvs/django_py3/lib/python3.5/site-packages/rest_framework/views.py", line 483, in dispatch
    response = self.handle_exception(exc)
  File "/home/elvira/.virtualenvs/django_py3/lib/python3.5/site-packages/rest_framework/views.py", line 443, in handle_exception
    self.raise_uncaught_exception(exc)
  File "/home/elvira/.virtualenvs/django_py3/lib/python3.5/site-packages/rest_framework/views.py", line 480, in dispatch
    response = handler(request, *args, **kwargs)
  File "/home/elvira/桌面/reposities/meiduo/meiduo/meiduo_mall/meiduo_mall/apps/verifications/views.py", line 37, in get
    pl.exectue()
AttributeError: 'StrictPipeline' object has no attribute 'exectue'
ERROR 2018-09-18 19:43:15,420 basehttp 124 "GET /sms_code/13955660980/ HTTP/1.1" 500 19295
INFO 2018-09-18 19:43:35,602 views 30 短信验证码为: 282334
INFO 2018-09-18 19:43:35,603 basehttp 124 "GET /sms_code/13955660980/ HTTP/1.1" 200 16
WARNING 2018-09-18 19:43:48,241 basehttp 124 "GET /sms_code/13955660980/ HTTP/1.1" 400 38
ERROR 2018-09-18 19:44:16,375 exception 80 Invalid HTTP_HOST header: 'www.meiduo.site:8000'. You may need to add 'www.meiduo.site' to ALLOWED_HOSTS.
WARNING 2018-09-18 19:44:16,442 basehttp 124 "GET / HTTP/1.1" 400 73362
ERROR 2018-09-18 19:44:16,564 exception 80 Invalid HTTP_HOST header: 'www.meiduo.site:8000'. You may need to add 'www.meiduo.site' to ALLOWED_HOSTS.
WARNING 2018-09-18 19:44:16,612 basehttp 124 "GET /favicon.ico HTTP/1.1" 400 73572
ERROR 2018-09-18 19:46:12,172 exception 135 Internal Server Error: /
Traceback (most recent call last):
  File "/home/elvira/.virtualenvs/django_py3/lib/python3.5/site-packages/django/core/handlers/exception.py", line 41, in inner
    response = get_response(request)
  File "/home/elvira/.virtualenvs/django_py3/lib/python3.5/site-packages/django/utils/deprecation.py", line 138, in __call__
    response = self.process_request(request)
  File "/home/elvira/.virtualenvs/django_py3/lib/python3.5/site-packages/django/middleware/common.py", line 57, in process_request
    host = request.get_host()
  File "/home/elvira/.virtualenvs/django_py3/lib/python3.5/site-packages/django/http/request.py", line 105, in get_host
    if domain and validate_host(domain, allowed_hosts):
  File "/home/elvira/.virtualenvs/django_py3/lib/python3.5/site-packages/django/http/request.py", line 579, in validate_host
    if pattern == '*' or is_same_domain(host, pattern):
  File "/home/elvira/.virtualenvs/django_py3/lib/python3.5/site-packages/django/utils/http.py", line 291, in is_same_domain
    pattern = pattern.lower()
AttributeError: 'list' object has no attribute 'lower'
ERROR 2018-09-18 19:46:12,304 basehttp 124 "GET / HTTP/1.1" 500 80442
ERROR 2018-09-18 19:46:12,441 exception 135 Internal Server Error: /favicon.ico
Traceback (most recent call last):
  File "/home/elvira/.virtualenvs/django_py3/lib/python3.5/site-packages/django/core/handlers/exception.py", line 41, in inner
    response = get_response(request)
  File "/home/elvira/.virtualenvs/django_py3/lib/python3.5/site-packages/django/utils/deprecation.py", line 138, in __call__
    response = self.process_request(request)
  File "/home/elvira/.virtualenvs/django_py3/lib/python3.5/site-packages/django/middleware/common.py", line 57, in process_request
    host = request.get_host()
  File "/home/elvira/.virtualenvs/django_py3/lib/python3.5/site-packages/django/http/request.py", line 105, in get_host
    if domain and validate_host(domain, allowed_hosts):
  File "/home/elvira/.virtualenvs/django_py3/lib/python3.5/site-packages/django/http/request.py", line 579, in validate_host
    if pattern == '*' or is_same_domain(host, pattern):
  File "/home/elvira/.virtualenvs/django_py3/lib/python3.5/site-packages/django/utils/http.py", line 291, in is_same_domain
    pattern = pattern.lower()
AttributeError: 'list' object has no attribute 'lower'
ERROR 2018-09-18 19:46:12,493 basehttp 124 "GET /favicon.ico HTTP/1.1" 500 80652
WARNING 2018-09-18 20:01:00,524 base 152 Not Found: /
WARNING 2018-09-18 20:01:00,525 basehttp 124 "GET / HTTP/1.1" 404 2110
WARNING 2018-09-18 20:01:00,557 base 152 Not Found: /favicon.ico
WARNING 2018-09-18 20:01:00,558 basehttp 124 "GET /favicon.ico HTTP/1.1" 404 2161
WARNING 2018-09-18 20:04:20,743 base 152 Not Found: /regiter.html
WARNING 2018-09-18 20:04:20,744 basehttp 124 "GET /regiter.html HTTP/1.1" 404 2164
ERROR 2018-09-18 20:18:35,287 exception 80 Invalid HTTP_HOST header: 'www.meiduo.site:8000'. You may need to add 'www.meiduo.site' to ALLOWED_HOSTS.
WARNING 2018-09-18 20:18:35,343 basehttp 124 "GET /sms_code/13955660980/ HTTP/1.1" 400 73298
ERROR 2018-09-18 20:19:05,268 exception 80 Invalid HTTP_HOST header: 'www.meiduo.site:8000'. You may need to add 'www.meiduo.site' to ALLOWED_HOSTS.
WARNING 2018-09-18 20:19:05,328 basehttp 124 "GET /sms_code/13955660980/ HTTP/1.1" 400 73190
WARNING 2018-09-19 10:22:56,830 base 152 Not Found: /sms_codes/13566778899/
INFO 2018-09-19 10:22:56,853 basehttp 124 "GET /mobiles/13566778899/count/ HTTP/1.1" 200 34
INFO 2018-09-19 10:22:56,854 basehttp 124 "GET /mobiles/13566778899/count/ HTTP/1.1" 200 34
WARNING 2018-09-19 10:22:56,871 basehttp 124 "GET /sms_codes/13566778899/ HTTP/1.1" 404 2582
INFO 2018-09-19 10:25:53,097 basehttp 124 "GET /mobiles/13566778899/count/ HTTP/1.1" 200 34
INFO 2018-09-19 10:25:53,232 basehttp 124 "GET /mobiles/13566778899/count/ HTTP/1.1" 200 34
ERROR 2018-09-19 10:25:53,247 exceptions 25 [<verifications.views.SMSCodesView object at 0x7f39a21f1668>] Error 111 connecting to 127.0.0.1:6379. Connection refused.
ERROR 2018-09-19 10:25:53,249 basehttp 124 "GET /sms_codes/13566778899/ HTTP/1.1" 507 35
INFO 2018-09-19 10:26:54,533 views 30 短信验证码为: 287564
INFO 2018-09-19 10:26:54,540 basehttp 124 "GET /mobiles/13566778899/count/ HTTP/1.1" 200 34
INFO 2018-09-19 10:26:54,622 basehttp 124 "GET /sms_codes/13566778899/ HTTP/1.1" 200 16
WARNING 2018-09-19 10:27:42,000 base 152 Not Found: /usernames/Elvira/count/
WARNING 2018-09-19 10:27:42,003 basehttp 124 "GET /usernames/Elvira/count/ HTTP/1.1" 404 2586
INFO 2018-09-19 10:27:58,245 views 30 短信验证码为: 286473
INFO 2018-09-19 10:27:58,249 basehttp 124 "GET /sms_codes/13566778899/ HTTP/1.1" 200 16
INFO 2018-09-19 10:27:58,253 basehttp 124 "GET /mobiles/13566778899/count/ HTTP/1.1" 200 34
WARNING 2018-09-19 10:28:10,167 base 152 Not Found: /usernames/Elvira/count/
WARNING 2018-09-19 10:28:10,171 basehttp 124 "GET /usernames/Elvira/count/ HTTP/1.1" 404 2586
INFO 2018-09-19 10:28:10,171 basehttp 124 "OPTIONS /users/ HTTP/1.1" 200 0
INFO 2018-09-19 10:28:10,177 basehttp 124 "GET /mobiles/13566778899/count/ HTTP/1.1" 200 34
WARNING 2018-09-19 10:28:10,183 base 152 Not Found: /users/
WARNING 2018-09-19 10:28:10,183 basehttp 124 "POST /users/ HTTP/1.1" 404 2536
INFO 2018-09-19 10:28:38,833 basehttp 124 "OPTIONS /users/ HTTP/1.1" 200 0
WARNING 2018-09-19 10:28:38,843 base 152 Not Found: /users/
WARNING 2018-09-19 10:28:38,847 basehttp 124 "POST /users/ HTTP/1.1" 404 2537
INFO 2018-09-19 10:28:38,849 basehttp 124 "GET /usernames/Elvira/count/ HTTP/1.1" 200 31
INFO 2018-09-19 10:28:38,854 basehttp 124 "GET /mobiles/13566778899/count/ HTTP/1.1" 200 34
INFO 2018-09-19 10:29:03,645 basehttp 124 "GET /usernames/Elvira/count/ HTTP/1.1" 200 31
INFO 2018-09-19 10:29:17,637 basehttp 124 "GET /mobiles/13566778899/count/ HTTP/1.1" 200 34
INFO 2018-09-19 10:29:17,774 views 30 短信验证码为: 254448
INFO 2018-09-19 10:29:17,782 basehttp 124 "GET /mobiles/13566778899/count/ HTTP/1.1" 200 34
INFO 2018-09-19 10:29:17,825 basehttp 124 "GET /sms_codes/13566778899/ HTTP/1.1" 200 16
INFO 2018-09-19 10:29:42,654 basehttp 124 "OPTIONS /users/ HTTP/1.1" 200 0
WARNING 2018-09-19 10:29:42,662 base 152 Not Found: /users/
WARNING 2018-09-19 10:29:42,663 basehttp 124 "POST /users/ HTTP/1.1" 404 2537
INFO 2018-09-19 10:29:42,668 basehttp 124 "GET /usernames/Elvira/count/ HTTP/1.1" 200 31
INFO 2018-09-19 10:29:42,672 basehttp 124 "GET /mobiles/13566778899/count/ HTTP/1.1" 200 34
INFO 2018-09-19 10:39:17,731 basehttp 124 "GET /usernames/Elvira/count/ HTTP/1.1" 200 31
INFO 2018-09-19 10:39:31,996 basehttp 124 "GET /mobiles/13566778899/count/ HTTP/1.1" 200 34
INFO 2018-09-19 10:39:32,137 views 30 短信验证码为: 891800
INFO 2018-09-19 10:39:32,143 basehttp 124 "GET /mobiles/13566778899/count/ HTTP/1.1" 200 34
INFO 2018-09-19 10:39:32,189 basehttp 124 "GET /sms_codes/13566778899/ HTTP/1.1" 200 16
INFO 2018-09-19 10:39:53,705 basehttp 124 "OPTIONS /users/ HTTP/1.1" 200 0
ERROR 2018-09-19 10:39:53,711 exception 135 Internal Server Error: /users/
Traceback (most recent call last):
  File "/home/elvira/.virtualenvs/django_py3/lib/python3.5/site-packages/django/core/handlers/exception.py", line 41, in inner
    response = get_response(request)
  File "/home/elvira/.virtualenvs/django_py3/lib/python3.5/site-packages/django/core/handlers/base.py", line 187, in _get_response
    response = self.process_exception_by_middleware(e, request)
  File "/home/elvira/.virtualenvs/django_py3/lib/python3.5/site-packages/django/core/handlers/base.py", line 185, in _get_response
    response = wrapped_callback(request, *callback_args, **callback_kwargs)
  File "/home/elvira/.virtualenvs/django_py3/lib/python3.5/site-packages/django/views/decorators/csrf.py", line 58, in wrapped_view
    return view_func(*args, **kwargs)
  File "/home/elvira/.virtualenvs/django_py3/lib/python3.5/site-packages/django/views/generic/base.py", line 68, in view
    return self.dispatch(request, *args, **kwargs)
  File "/home/elvira/.virtualenvs/django_py3/lib/python3.5/site-packages/rest_framework/views.py", line 483, in dispatch
    response = self.handle_exception(exc)
  File "/home/elvira/.virtualenvs/django_py3/lib/python3.5/site-packages/rest_framework/views.py", line 443, in handle_exception
    self.raise_uncaught_exception(exc)
  File "/home/elvira/.virtualenvs/django_py3/lib/python3.5/site-packages/rest_framework/views.py", line 480, in dispatch
    response = handler(request, *args, **kwargs)
  File "/home/elvira/.virtualenvs/django_py3/lib/python3.5/site-packages/rest_framework/generics.py", line 192, in post
    return self.create(request, *args, **kwargs)
  File "/home/elvira/.virtualenvs/django_py3/lib/python3.5/site-packages/rest_framework/mixins.py", line 19, in create
    serializer = self.get_serializer(data=request.data)
  File "/home/elvira/.virtualenvs/django_py3/lib/python3.5/site-packages/rest_framework/generics.py", line 112, in get_serializer
    return serializer_class(*args, **kwargs)
TypeError: 'module' object is not callable
INFO 2018-09-19 10:39:53,713 basehttp 124 "GET /usernames/Elvira/count/ HTTP/1.1" 200 31
INFO 2018-09-19 10:39:53,715 basehttp 124 "GET /mobiles/13566778899/count/ HTTP/1.1" 200 34
ERROR 2018-09-19 10:39:53,946 basehttp 124 "POST /users/ HTTP/1.1" 500 20262
INFO 2018-09-19 10:42:39,429 basehttp 124 "OPTIONS /users/ HTTP/1.1" 200 0
INFO 2018-09-19 10:42:39,442 basehttp 124 "GET /mobiles/13566778899/count/ HTTP/1.1" 200 34
INFO 2018-09-19 10:42:39,442 basehttp 124 "GET /usernames/Elvira/count/ HTTP/1.1" 200 31
ERROR 2018-09-19 10:42:39,444 exception 135 Internal Server Error: /users/
Traceback (most recent call last):
  File "/home/elvira/.virtualenvs/django_py3/lib/python3.5/site-packages/django/core/handlers/exception.py", line 41, in inner
    response = get_response(request)
  File "/home/elvira/.virtualenvs/django_py3/lib/python3.5/site-packages/django/core/handlers/base.py", line 187, in _get_response
    response = self.process_exception_by_middleware(e, request)
  File "/home/elvira/.virtualenvs/django_py3/lib/python3.5/site-packages/django/core/handlers/base.py", line 185, in _get_response
    response = wrapped_callback(request, *callback_args, **callback_kwargs)
  File "/home/elvira/.virtualenvs/django_py3/lib/python3.5/site-packages/django/views/decorators/csrf.py", line 58, in wrapped_view
    return view_func(*args, **kwargs)
  File "/home/elvira/.virtualenvs/django_py3/lib/python3.5/site-packages/django/views/generic/base.py", line 68, in view
    return self.dispatch(request, *args, **kwargs)
  File "/home/elvira/.virtualenvs/django_py3/lib/python3.5/site-packages/rest_framework/views.py", line 483, in dispatch
    response = self.handle_exception(exc)
  File "/home/elvira/.virtualenvs/django_py3/lib/python3.5/site-packages/rest_framework/views.py", line 443, in handle_exception
    self.raise_uncaught_exception(exc)
  File "/home/elvira/.virtualenvs/django_py3/lib/python3.5/site-packages/rest_framework/views.py", line 480, in dispatch
    response = handler(request, *args, **kwargs)
  File "/home/elvira/.virtualenvs/django_py3/lib/python3.5/site-packages/rest_framework/generics.py", line 192, in post
    return self.create(request, *args, **kwargs)
  File "/home/elvira/.virtualenvs/django_py3/lib/python3.5/site-packages/rest_framework/mixins.py", line 19, in create
    serializer = self.get_serializer(data=request.data)
  File "/home/elvira/.virtualenvs/django_py3/lib/python3.5/site-packages/rest_framework/generics.py", line 112, in get_serializer
    return serializer_class(*args, **kwargs)
TypeError: 'module' object is not callable
ERROR 2018-09-19 10:42:39,506 basehttp 124 "POST /users/ HTTP/1.1" 500 20353
INFO 2018-09-19 10:43:46,022 basehttp 124 "OPTIONS /users/ HTTP/1.1" 200 0
INFO 2018-09-19 10:43:46,034 basehttp 124 "GET /usernames/Elvira/count/ HTTP/1.1" 200 31
INFO 2018-09-19 10:43:46,035 basehttp 124 "GET /mobiles/13566778899/count/ HTTP/1.1" 200 34
ERROR 2018-09-19 10:43:46,037 exception 135 Internal Server Error: /users/
Traceback (most recent call last):
  File "/home/elvira/.virtualenvs/django_py3/lib/python3.5/site-packages/django/core/handlers/exception.py", line 41, in inner
    response = get_response(request)
  File "/home/elvira/.virtualenvs/django_py3/lib/python3.5/site-packages/django/core/handlers/base.py", line 187, in _get_response
    response = self.process_exception_by_middleware(e, request)
  File "/home/elvira/.virtualenvs/django_py3/lib/python3.5/site-packages/django/core/handlers/base.py", line 185, in _get_response
    response = wrapped_callback(request, *callback_args, **callback_kwargs)
  File "/home/elvira/.virtualenvs/django_py3/lib/python3.5/site-packages/django/views/decorators/csrf.py", line 58, in wrapped_view
    return view_func(*args, **kwargs)
  File "/home/elvira/.virtualenvs/django_py3/lib/python3.5/site-packages/django/views/generic/base.py", line 68, in view
    return self.dispatch(request, *args, **kwargs)
  File "/home/elvira/.virtualenvs/django_py3/lib/python3.5/site-packages/rest_framework/views.py", line 483, in dispatch
    response = self.handle_exception(exc)
  File "/home/elvira/.virtualenvs/django_py3/lib/python3.5/site-packages/rest_framework/views.py", line 443, in handle_exception
    self.raise_uncaught_exception(exc)
  File "/home/elvira/.virtualenvs/django_py3/lib/python3.5/site-packages/rest_framework/views.py", line 480, in dispatch
    response = handler(request, *args, **kwargs)
  File "/home/elvira/.virtualenvs/django_py3/lib/python3.5/site-packages/rest_framework/generics.py", line 192, in post
    return self.create(request, *args, **kwargs)
  File "/home/elvira/.virtualenvs/django_py3/lib/python3.5/site-packages/rest_framework/mixins.py", line 19, in create
    serializer = self.get_serializer(data=request.data)
  File "/home/elvira/.virtualenvs/django_py3/lib/python3.5/site-packages/rest_framework/generics.py", line 112, in get_serializer
    return serializer_class(*args, **kwargs)
TypeError: 'module' object is not callable
ERROR 2018-09-19 10:43:46,102 basehttp 124 "POST /users/ HTTP/1.1" 500 20353
INFO 2018-09-19 10:45:19,537 basehttp 124 "GET /usernames/Elvira/count/ HTTP/1.1" 200 31
INFO 2018-09-19 10:45:34,020 basehttp 124 "GET /mobiles/13566778899/count/ HTTP/1.1" 200 34
INFO 2018-09-19 10:45:34,206 views 30 短信验证码为: 627175
INFO 2018-09-19 10:45:34,216 basehttp 124 "GET /mobiles/13566778899/count/ HTTP/1.1" 200 34
INFO 2018-09-19 10:45:34,259 basehttp 124 "GET /sms_codes/13566778899/ HTTP/1.1" 200 16
INFO 2018-09-19 10:46:09,883 basehttp 124 "OPTIONS /users/ HTTP/1.1" 200 0
ERROR 2018-09-19 10:46:09,890 exception 135 Internal Server Error: /users/
Traceback (most recent call last):
  File "/home/elvira/.virtualenvs/django_py3/lib/python3.5/site-packages/django/core/handlers/exception.py", line 41, in inner
    response = get_response(request)
  File "/home/elvira/.virtualenvs/django_py3/lib/python3.5/site-packages/django/core/handlers/base.py", line 187, in _get_response
    response = self.process_exception_by_middleware(e, request)
  File "/home/elvira/.virtualenvs/django_py3/lib/python3.5/site-packages/django/core/handlers/base.py", line 185, in _get_response
    response = wrapped_callback(request, *callback_args, **callback_kwargs)
  File "/home/elvira/.virtualenvs/django_py3/lib/python3.5/site-packages/django/views/decorators/csrf.py", line 58, in wrapped_view
    return view_func(*args, **kwargs)
  File "/home/elvira/.virtualenvs/django_py3/lib/python3.5/site-packages/django/views/generic/base.py", line 68, in view
    return self.dispatch(request, *args, **kwargs)
  File "/home/elvira/.virtualenvs/django_py3/lib/python3.5/site-packages/rest_framework/views.py", line 483, in dispatch
    response = self.handle_exception(exc)
  File "/home/elvira/.virtualenvs/django_py3/lib/python3.5/site-packages/rest_framework/views.py", line 443, in handle_exception
    self.raise_uncaught_exception(exc)
  File "/home/elvira/.virtualenvs/django_py3/lib/python3.5/site-packages/rest_framework/views.py", line 480, in dispatch
    response = handler(request, *args, **kwargs)
  File "/home/elvira/.virtualenvs/django_py3/lib/python3.5/site-packages/rest_framework/generics.py", line 192, in post
    return self.create(request, *args, **kwargs)
  File "/home/elvira/.virtualenvs/django_py3/lib/python3.5/site-packages/rest_framework/mixins.py", line 19, in create
    serializer = self.get_serializer(data=request.data)
  File "/home/elvira/.virtualenvs/django_py3/lib/python3.5/site-packages/rest_framework/generics.py", line 112, in get_serializer
    return serializer_class(*args, **kwargs)
TypeError: 'module' object is not callable
INFO 2018-09-19 10:46:09,893 basehttp 124 "GET /usernames/Elvira/count/ HTTP/1.1" 200 31
INFO 2018-09-19 10:46:09,908 basehttp 124 "GET /mobiles/13566778899/count/ HTTP/1.1" 200 34
ERROR 2018-09-19 10:46:09,941 basehttp 124 "POST /users/ HTTP/1.1" 500 20353
INFO 2018-09-19 11:43:08,317 basehttp 124 "GET /usernames/Elvira/count/ HTTP/1.1" 200 31
INFO 2018-09-19 11:43:20,606 basehttp 124 "GET /mobiles/13566778899/count/ HTTP/1.1" 200 34
INFO 2018-09-19 11:43:21,539 views 30 短信验证码为: 173117
INFO 2018-09-19 11:43:21,568 basehttp 124 "GET /mobiles/13566778899/count/ HTTP/1.1" 200 34
INFO 2018-09-19 11:43:21,618 basehttp 124 "GET /sms_codes/13566778899/ HTTP/1.1" 200 16
INFO 2018-09-19 11:43:35,050 basehttp 124 "OPTIONS /users/ HTTP/1.1" 200 0
ERROR 2018-09-19 11:43:35,055 exception 135 Internal Server Error: /users/
Traceback (most recent call last):
  File "/home/elvira/.virtualenvs/django_py3/lib/python3.5/site-packages/django/core/handlers/exception.py", line 41, in inner
    response = get_response(request)
  File "/home/elvira/.virtualenvs/django_py3/lib/python3.5/site-packages/django/core/handlers/base.py", line 187, in _get_response
    response = self.process_exception_by_middleware(e, request)
  File "/home/elvira/.virtualenvs/django_py3/lib/python3.5/site-packages/django/core/handlers/base.py", line 185, in _get_response
    response = wrapped_callback(request, *callback_args, **callback_kwargs)
  File "/home/elvira/.virtualenvs/django_py3/lib/python3.5/site-packages/django/views/decorators/csrf.py", line 58, in wrapped_view
    return view_func(*args, **kwargs)
  File "/home/elvira/.virtualenvs/django_py3/lib/python3.5/site-packages/django/views/generic/base.py", line 68, in view
    return self.dispatch(request, *args, **kwargs)
  File "/home/elvira/.virtualenvs/django_py3/lib/python3.5/site-packages/rest_framework/views.py", line 483, in dispatch
    response = self.handle_exception(exc)
  File "/home/elvira/.virtualenvs/django_py3/lib/python3.5/site-packages/rest_framework/views.py", line 443, in handle_exception
    self.raise_uncaught_exception(exc)
  File "/home/elvira/.virtualenvs/django_py3/lib/python3.5/site-packages/rest_framework/views.py", line 480, in dispatch
    response = handler(request, *args, **kwargs)
  File "/home/elvira/.virtualenvs/django_py3/lib/python3.5/site-packages/rest_framework/generics.py", line 192, in post
    return self.create(request, *args, **kwargs)
  File "/home/elvira/.virtualenvs/django_py3/lib/python3.5/site-packages/rest_framework/mixins.py", line 19, in create
    serializer = self.get_serializer(data=request.data)
  File "/home/elvira/.virtualenvs/django_py3/lib/python3.5/site-packages/rest_framework/generics.py", line 112, in get_serializer
    return serializer_class(*args, **kwargs)
TypeError: 'module' object is not callable
INFO 2018-09-19 11:43:35,059 basehttp 124 "GET /mobiles/13566778899/count/ HTTP/1.1" 200 34
INFO 2018-09-19 11:43:35,062 basehttp 124 "GET /usernames/Elvira/count/ HTTP/1.1" 200 31
ERROR 2018-09-19 11:43:35,099 basehttp 124 "POST /users/ HTTP/1.1" 500 20425
INFO 2018-09-19 11:46:25,161 basehttp 124 "OPTIONS /users/ HTTP/1.1" 200 0
INFO 2018-09-19 11:46:25,176 basehttp 124 "GET /mobiles/13566778899/count/ HTTP/1.1" 200 34
ERROR 2018-09-19 11:46:25,184 exception 135 Internal Server Error: /users/
Traceback (most recent call last):
  File "/home/elvira/.virtualenvs/django_py3/lib/python3.5/site-packages/django/core/handlers/exception.py", line 41, in inner
    response = get_response(request)
  File "/home/elvira/.virtualenvs/django_py3/lib/python3.5/site-packages/django/core/handlers/base.py", line 187, in _get_response
    response = self.process_exception_by_middleware(e, request)
  File "/home/elvira/.virtualenvs/django_py3/lib/python3.5/site-packages/django/core/handlers/base.py", line 185, in _get_response
    response = wrapped_callback(request, *callback_args, **callback_kwargs)
  File "/home/elvira/.virtualenvs/django_py3/lib/python3.5/site-packages/django/views/decorators/csrf.py", line 58, in wrapped_view
    return view_func(*args, **kwargs)
  File "/home/elvira/.virtualenvs/django_py3/lib/python3.5/site-packages/django/views/generic/base.py", line 68, in view
    return self.dispatch(request, *args, **kwargs)
  File "/home/elvira/.virtualenvs/django_py3/lib/python3.5/site-packages/rest_framework/views.py", line 483, in dispatch
    response = self.handle_exception(exc)
  File "/home/elvira/.virtualenvs/django_py3/lib/python3.5/site-packages/rest_framework/views.py", line 443, in handle_exception
    self.raise_uncaught_exception(exc)
  File "/home/elvira/.virtualenvs/django_py3/lib/python3.5/site-packages/rest_framework/views.py", line 480, in dispatch
    response = handler(request, *args, **kwargs)
  File "/home/elvira/.virtualenvs/django_py3/lib/python3.5/site-packages/rest_framework/generics.py", line 192, in post
    return self.create(request, *args, **kwargs)
  File "/home/elvira/.virtualenvs/django_py3/lib/python3.5/site-packages/rest_framework/mixins.py", line 19, in create
    serializer = self.get_serializer(data=request.data)
  File "/home/elvira/.virtualenvs/django_py3/lib/python3.5/site-packages/rest_framework/generics.py", line 112, in get_serializer
    return serializer_class(*args, **kwargs)
TypeError: 'module' object is not callable
INFO 2018-09-19 11:46:25,196 basehttp 124 "GET /usernames/Elvira/count/ HTTP/1.1" 200 31
ERROR 2018-09-19 11:46:25,258 basehttp 124 "POST /users/ HTTP/1.1" 500 20425
INFO 2018-09-19 11:46:50,256 basehttp 124 "OPTIONS /users/ HTTP/1.1" 200 0
ERROR 2018-09-19 11:46:50,262 exception 135 Internal Server Error: /users/
Traceback (most recent call last):
  File "/home/elvira/.virtualenvs/django_py3/lib/python3.5/site-packages/django/core/handlers/exception.py", line 41, in inner
    response = get_response(request)
  File "/home/elvira/.virtualenvs/django_py3/lib/python3.5/site-packages/django/core/handlers/base.py", line 187, in _get_response
    response = self.process_exception_by_middleware(e, request)
  File "/home/elvira/.virtualenvs/django_py3/lib/python3.5/site-packages/django/core/handlers/base.py", line 185, in _get_response
    response = wrapped_callback(request, *callback_args, **callback_kwargs)
  File "/home/elvira/.virtualenvs/django_py3/lib/python3.5/site-packages/django/views/decorators/csrf.py", line 58, in wrapped_view
    return view_func(*args, **kwargs)
  File "/home/elvira/.virtualenvs/django_py3/lib/python3.5/site-packages/django/views/generic/base.py", line 68, in view
    return self.dispatch(request, *args, **kwargs)
  File "/home/elvira/.virtualenvs/django_py3/lib/python3.5/site-packages/rest_framework/views.py", line 483, in dispatch
    response = self.handle_exception(exc)
  File "/home/elvira/.virtualenvs/django_py3/lib/python3.5/site-packages/rest_framework/views.py", line 443, in handle_exception
    self.raise_uncaught_exception(exc)
  File "/home/elvira/.virtualenvs/django_py3/lib/python3.5/site-packages/rest_framework/views.py", line 480, in dispatch
    response = handler(request, *args, **kwargs)
  File "/home/elvira/.virtualenvs/django_py3/lib/python3.5/site-packages/rest_framework/generics.py", line 192, in post
    return self.create(request, *args, **kwargs)
  File "/home/elvira/.virtualenvs/django_py3/lib/python3.5/site-packages/rest_framework/mixins.py", line 19, in create
    serializer = self.get_serializer(data=request.data)
  File "/home/elvira/.virtualenvs/django_py3/lib/python3.5/site-packages/rest_framework/generics.py", line 112, in get_serializer
    return serializer_class(*args, **kwargs)
TypeError: 'module' object is not callable
INFO 2018-09-19 11:46:50,287 basehttp 124 "GET /mobiles/13566778899/count/ HTTP/1.1" 200 34
INFO 2018-09-19 11:46:50,297 basehttp 124 "GET /usernames/Elvira/count/ HTTP/1.1" 200 31
ERROR 2018-09-19 11:46:50,313 basehttp 124 "POST /users/ HTTP/1.1" 500 20425
INFO 2018-09-19 11:51:28,377 basehttp 124 "GET /usernames/Elvira/count/ HTTP/1.1" 200 31
INFO 2018-09-19 11:51:44,720 basehttp 124 "GET /mobiles/13566778899/count/ HTTP/1.1" 200 34
INFO 2018-09-19 11:51:44,888 views 30 短信验证码为: 901181
INFO 2018-09-19 11:51:44,896 basehttp 124 "GET /mobiles/13566778899/count/ HTTP/1.1" 200 34
INFO 2018-09-19 11:51:44,962 basehttp 124 "GET /sms_codes/13566778899/ HTTP/1.1" 200 16
INFO 2018-09-19 11:52:03,865 basehttp 124 "OPTIONS /users/ HTTP/1.1" 200 0
INFO 2018-09-19 11:52:03,872 basehttp 124 "GET /usernames/Elvira/count/ HTTP/1.1" 200 31
INFO 2018-09-19 11:52:03,887 basehttp 124 "GET /mobiles/13566778899/count/ HTTP/1.1" 200 34
ERROR 2018-09-19 11:52:03,888 exception 135 Internal Server Error: /users/
Traceback (most recent call last):
  File "/home/elvira/.virtualenvs/django_py3/lib/python3.5/site-packages/django/core/handlers/exception.py", line 41, in inner
    response = get_response(request)
  File "/home/elvira/.virtualenvs/django_py3/lib/python3.5/site-packages/django/core/handlers/base.py", line 187, in _get_response
    response = self.process_exception_by_middleware(e, request)
  File "/home/elvira/.virtualenvs/django_py3/lib/python3.5/site-packages/django/core/handlers/base.py", line 185, in _get_response
    response = wrapped_callback(request, *callback_args, **callback_kwargs)
  File "/home/elvira/.virtualenvs/django_py3/lib/python3.5/site-packages/django/views/decorators/csrf.py", line 58, in wrapped_view
    return view_func(*args, **kwargs)
  File "/home/elvira/.virtualenvs/django_py3/lib/python3.5/site-packages/django/views/generic/base.py", line 68, in view
    return self.dispatch(request, *args, **kwargs)
  File "/home/elvira/.virtualenvs/django_py3/lib/python3.5/site-packages/rest_framework/views.py", line 483, in dispatch
    response = self.handle_exception(exc)
  File "/home/elvira/.virtualenvs/django_py3/lib/python3.5/site-packages/rest_framework/views.py", line 443, in handle_exception
    self.raise_uncaught_exception(exc)
  File "/home/elvira/.virtualenvs/django_py3/lib/python3.5/site-packages/rest_framework/views.py", line 480, in dispatch
    response = handler(request, *args, **kwargs)
  File "/home/elvira/.virtualenvs/django_py3/lib/python3.5/site-packages/rest_framework/generics.py", line 192, in post
    return self.create(request, *args, **kwargs)
  File "/home/elvira/.virtualenvs/django_py3/lib/python3.5/site-packages/rest_framework/mixins.py", line 19, in create
    serializer = self.get_serializer(data=request.data)
  File "/home/elvira/.virtualenvs/django_py3/lib/python3.5/site-packages/rest_framework/generics.py", line 112, in get_serializer
    return serializer_class(*args, **kwargs)
TypeError: 'module' object is not callable
ERROR 2018-09-19 11:52:03,970 basehttp 124 "POST /users/ HTTP/1.1" 500 20401
INFO 2018-09-19 12:11:59,192 basehttp 124 "GET /usernames/Elvira/count/ HTTP/1.1" 200 31
INFO 2018-09-19 12:12:28,909 basehttp 124 "GET /mobiles/13566778899/count/ HTTP/1.1" 200 34
INFO 2018-09-19 12:12:29,085 views 30 短信验证码为: 027045
INFO 2018-09-19 12:12:29,111 basehttp 124 "GET /mobiles/13566778899/count/ HTTP/1.1" 200 34
INFO 2018-09-19 12:12:29,163 basehttp 124 "GET /sms_codes/13566778899/ HTTP/1.1" 200 16
INFO 2018-09-19 12:12:46,946 basehttp 124 "OPTIONS /users/ HTTP/1.1" 200 0
INFO 2018-09-19 12:12:46,958 basehttp 124 "GET /usernames/Elvira/count/ HTTP/1.1" 200 31
INFO 2018-09-19 12:12:46,965 basehttp 124 "GET /mobiles/13566778899/count/ HTTP/1.1" 200 34
ERROR 2018-09-19 12:12:46,966 exception 135 Internal Server Error: /users/
Traceback (most recent call last):
  File "/home/elvira/.virtualenvs/django_py3/lib/python3.5/site-packages/django/core/handlers/exception.py", line 41, in inner
    response = get_response(request)
  File "/home/elvira/.virtualenvs/django_py3/lib/python3.5/site-packages/django/core/handlers/base.py", line 187, in _get_response
    response = self.process_exception_by_middleware(e, request)
  File "/home/elvira/.virtualenvs/django_py3/lib/python3.5/site-packages/django/core/handlers/base.py", line 185, in _get_response
    response = wrapped_callback(request, *callback_args, **callback_kwargs)
  File "/home/elvira/.virtualenvs/django_py3/lib/python3.5/site-packages/django/views/decorators/csrf.py", line 58, in wrapped_view
    return view_func(*args, **kwargs)
  File "/home/elvira/.virtualenvs/django_py3/lib/python3.5/site-packages/django/views/generic/base.py", line 68, in view
    return self.dispatch(request, *args, **kwargs)
  File "/home/elvira/.virtualenvs/django_py3/lib/python3.5/site-packages/rest_framework/views.py", line 483, in dispatch
    response = self.handle_exception(exc)
  File "/home/elvira/.virtualenvs/django_py3/lib/python3.5/site-packages/rest_framework/views.py", line 443, in handle_exception
    self.raise_uncaught_exception(exc)
  File "/home/elvira/.virtualenvs/django_py3/lib/python3.5/site-packages/rest_framework/views.py", line 480, in dispatch
    response = handler(request, *args, **kwargs)
  File "/home/elvira/.virtualenvs/django_py3/lib/python3.5/site-packages/rest_framework/generics.py", line 192, in post
    return self.create(request, *args, **kwargs)
  File "/home/elvira/.virtualenvs/django_py3/lib/python3.5/site-packages/rest_framework/mixins.py", line 19, in create
    serializer = self.get_serializer(data=request.data)
  File "/home/elvira/.virtualenvs/django_py3/lib/python3.5/site-packages/rest_framework/generics.py", line 112, in get_serializer
    return serializer_class(*args, **kwargs)
TypeError: 'module' object is not callable
ERROR 2018-09-19 12:12:47,030 basehttp 124 "POST /users/ HTTP/1.1" 500 20425
INFO 2018-09-19 12:14:56,938 basehttp 124 "OPTIONS /users/ HTTP/1.1" 200 0
ERROR 2018-09-19 12:14:56,950 exception 135 Internal Server Error: /users/
Traceback (most recent call last):
  File "/home/elvira/.virtualenvs/django_py3/lib/python3.5/site-packages/django/core/handlers/exception.py", line 41, in inner
    response = get_response(request)
  File "/home/elvira/.virtualenvs/django_py3/lib/python3.5/site-packages/django/core/handlers/base.py", line 187, in _get_response
    response = self.process_exception_by_middleware(e, request)
  File "/home/elvira/.virtualenvs/django_py3/lib/python3.5/site-packages/django/core/handlers/base.py", line 185, in _get_response
    response = wrapped_callback(request, *callback_args, **callback_kwargs)
  File "/home/elvira/.virtualenvs/django_py3/lib/python3.5/site-packages/django/views/decorators/csrf.py", line 58, in wrapped_view
    return view_func(*args, **kwargs)
  File "/home/elvira/.virtualenvs/django_py3/lib/python3.5/site-packages/django/views/generic/base.py", line 68, in view
    return self.dispatch(request, *args, **kwargs)
  File "/home/elvira/.virtualenvs/django_py3/lib/python3.5/site-packages/rest_framework/views.py", line 483, in dispatch
    response = self.handle_exception(exc)
  File "/home/elvira/.virtualenvs/django_py3/lib/python3.5/site-packages/rest_framework/views.py", line 443, in handle_exception
    self.raise_uncaught_exception(exc)
  File "/home/elvira/.virtualenvs/django_py3/lib/python3.5/site-packages/rest_framework/views.py", line 480, in dispatch
    response = handler(request, *args, **kwargs)
  File "/home/elvira/.virtualenvs/django_py3/lib/python3.5/site-packages/rest_framework/generics.py", line 192, in post
    return self.create(request, *args, **kwargs)
  File "/home/elvira/.virtualenvs/django_py3/lib/python3.5/site-packages/rest_framework/mixins.py", line 19, in create
    serializer = self.get_serializer(data=request.data)
  File "/home/elvira/.virtualenvs/django_py3/lib/python3.5/site-packages/rest_framework/generics.py", line 112, in get_serializer
    return serializer_class(*args, **kwargs)
TypeError: 'module' object is not callable
INFO 2018-09-19 12:14:56,968 basehttp 124 "GET /usernames/Elvira/count/ HTTP/1.1" 200 31
INFO 2018-09-19 12:14:56,970 basehttp 124 "GET /mobiles/13566778899/count/ HTTP/1.1" 200 34
ERROR 2018-09-19 12:14:57,076 basehttp 124 "POST /users/ HTTP/1.1" 500 20354
WARNING 2018-09-19 12:15:30,676 base 152 Not Found: /
WARNING 2018-09-19 12:15:30,676 basehttp 124 "GET / HTTP/1.1" 404 2821
WARNING 2018-09-19 12:15:30,756 base 152 Not Found: /favicon.ico
WARNING 2018-09-19 12:15:30,768 basehttp 124 "GET /favicon.ico HTTP/1.1" 404 2872
INFO 2018-09-19 12:15:43,915 basehttp 124 "GET /admin HTTP/1.1" 301 0
INFO 2018-09-19 12:15:43,962 basehttp 124 "GET /admin/ HTTP/1.1" 302 0
INFO 2018-09-19 12:15:44,205 basehttp 124 "GET /admin/login/?next=/admin/ HTTP/1.1" 200 1652
INFO 2018-09-19 12:15:44,285 basehttp 124 "GET /static/admin/css/login.css HTTP/1.1" 200 1203
INFO 2018-09-19 12:15:44,286 basehttp 124 "GET /static/admin/css/base.css HTTP/1.1" 200 16066
INFO 2018-09-19 12:15:44,293 basehttp 124 "GET /static/admin/css/fonts.css HTTP/1.1" 200 423
INFO 2018-09-19 12:15:44,328 basehttp 124 "GET /static/admin/fonts/Roboto-Regular-webfont.woff HTTP/1.1" 200 80304
INFO 2018-09-19 12:15:44,328 basehttp 124 "GET /static/admin/fonts/Roboto-Light-webfont.woff HTTP/1.1" 200 81348
INFO 2018-09-19 12:15:54,453 basehttp 124 "POST /admin/login/?next=/admin/ HTTP/1.1" 200 1784
INFO 2018-09-19 12:15:54,504 basehttp 124 "GET /static/admin/fonts/Roboto-Bold-webfont.woff HTTP/1.1" 200 82564
INFO 2018-09-19 12:16:01,052 basehttp 124 "GET /admin/login/?next=/admin/ HTTP/1.1" 200 1652
WARNING 2018-09-19 12:16:27,094 base 152 Not Found: /sms_code/13255668899/
WARNING 2018-09-19 12:16:27,095 basehttp 124 "GET /sms_code/13255668899/ HTTP/1.1" 404 2902
INFO 2018-09-19 12:16:44,565 views 30 短信验证码为: 822385
INFO 2018-09-19 12:16:44,708 basehttp 124 "GET /sms_codes/13255668899/ HTTP/1.1" 200 5235
INFO 2018-09-19 12:16:44,756 basehttp 124 "GET /static/rest_framework/css/default.css HTTP/1.1" 200 1131
INFO 2018-09-19 12:16:44,757 basehttp 124 "GET /static/rest_framework/css/bootstrap-tweaks.css HTTP/1.1" 200 3385
INFO 2018-09-19 12:16:44,759 basehttp 124 "GET /static/rest_framework/css/prettify.css HTTP/1.1" 200 817
INFO 2018-09-19 12:16:44,759 basehttp 124 "GET /static/rest_framework/css/bootstrap.min.css HTTP/1.1" 200 121200
INFO 2018-09-19 12:16:44,759 basehttp 124 "GET /static/rest_framework/js/ajax-form.js HTTP/1.1" 200 3597
INFO 2018-09-19 12:16:44,761 basehttp 124 "GET /static/rest_framework/js/jquery-3.3.1.min.js HTTP/1.1" 200 86927
INFO 2018-09-19 12:16:44,807 basehttp 124 "GET /static/rest_framework/js/csrf.js HTTP/1.1" 200 1735
INFO 2018-09-19 12:16:44,808 basehttp 124 "GET /static/rest_framework/js/default.js HTTP/1.1" 200 1262
INFO 2018-09-19 12:16:44,809 basehttp 124 "GET /static/rest_framework/js/prettify-min.js HTTP/1.1" 200 13632
INFO 2018-09-19 12:16:44,817 basehttp 124 "GET /static/rest_framework/js/bootstrap.min.js HTTP/1.1" 200 37045
INFO 2018-09-19 12:16:44,823 basehttp 124 "GET /static/rest_framework/img/grid.png HTTP/1.1" 200 1458
ERROR 2018-09-19 12:16:57,220 exception 135 Internal Server Error: /users/
Traceback (most recent call last):
  File "/home/elvira/.virtualenvs/django_py3/lib/python3.5/site-packages/django/core/handlers/exception.py", line 41, in inner
    response = get_response(request)
  File "/home/elvira/.virtualenvs/django_py3/lib/python3.5/site-packages/django/core/handlers/base.py", line 217, in _get_response
    response = self.process_exception_by_middleware(e, request)
  File "/home/elvira/.virtualenvs/django_py3/lib/python3.5/site-packages/django/core/handlers/base.py", line 215, in _get_response
    response = response.render()
  File "/home/elvira/.virtualenvs/django_py3/lib/python3.5/site-packages/django/template/response.py", line 107, in render
    self.content = self.rendered_content
  File "/home/elvira/.virtualenvs/django_py3/lib/python3.5/site-packages/rest_framework/response.py", line 72, in rendered_content
    ret = renderer.render(self.data, accepted_media_type, context)
  File "/home/elvira/.virtualenvs/django_py3/lib/python3.5/site-packages/rest_framework/renderers.py", line 724, in render
    context = self.get_context(data, accepted_media_type, renderer_context)
  File "/home/elvira/.virtualenvs/django_py3/lib/python3.5/site-packages/rest_framework/renderers.py", line 656, in get_context
    raw_data_post_form = self.get_raw_data_form(data, view, 'POST', request)
  File "/home/elvira/.virtualenvs/django_py3/lib/python3.5/site-packages/rest_framework/renderers.py", line 563, in get_raw_data_form
    serializer = view.get_serializer()
  File "/home/elvira/.virtualenvs/django_py3/lib/python3.5/site-packages/rest_framework/generics.py", line 112, in get_serializer
    return serializer_class(*args, **kwargs)
TypeError: 'module' object is not callable
ERROR 2018-09-19 12:16:57,329 basehttp 124 "GET /users/ HTTP/1.1" 500 103351
INFO 2018-09-19 12:26:29,236 basehttp 124 "GET /usernames/Elvira/count/ HTTP/1.1" 200 31
INFO 2018-09-19 12:26:39,058 basehttp 124 "GET /mobiles/13566778899/count/ HTTP/1.1" 200 34
INFO 2018-09-19 12:26:40,560 views 30 短信验证码为: 306188
INFO 2018-09-19 12:26:40,566 basehttp 124 "GET /sms_codes/13566778899/ HTTP/1.1" 200 16
INFO 2018-09-19 12:26:40,573 basehttp 124 "GET /mobiles/13566778899/count/ HTTP/1.1" 200 34
INFO 2018-09-19 12:26:57,743 basehttp 124 "OPTIONS /users/ HTTP/1.1" 200 0
ERROR 2018-09-19 12:26:57,748 exception 135 Internal Server Error: /users/
Traceback (most recent call last):
  File "/home/elvira/.virtualenvs/django_py3/lib/python3.5/site-packages/django/core/handlers/exception.py", line 41, in inner
    response = get_response(request)
  File "/home/elvira/.virtualenvs/django_py3/lib/python3.5/site-packages/django/core/handlers/base.py", line 187, in _get_response
    response = self.process_exception_by_middleware(e, request)
  File "/home/elvira/.virtualenvs/django_py3/lib/python3.5/site-packages/django/core/handlers/base.py", line 185, in _get_response
    response = wrapped_callback(request, *callback_args, **callback_kwargs)
  File "/home/elvira/.virtualenvs/django_py3/lib/python3.5/site-packages/django/views/decorators/csrf.py", line 58, in wrapped_view
    return view_func(*args, **kwargs)
  File "/home/elvira/.virtualenvs/django_py3/lib/python3.5/site-packages/django/views/generic/base.py", line 68, in view
    return self.dispatch(request, *args, **kwargs)
  File "/home/elvira/.virtualenvs/django_py3/lib/python3.5/site-packages/rest_framework/views.py", line 483, in dispatch
    response = self.handle_exception(exc)
  File "/home/elvira/.virtualenvs/django_py3/lib/python3.5/site-packages/rest_framework/views.py", line 443, in handle_exception
    self.raise_uncaught_exception(exc)
  File "/home/elvira/.virtualenvs/django_py3/lib/python3.5/site-packages/rest_framework/views.py", line 480, in dispatch
    response = handler(request, *args, **kwargs)
  File "/home/elvira/.virtualenvs/django_py3/lib/python3.5/site-packages/rest_framework/generics.py", line 192, in post
    return self.create(request, *args, **kwargs)
  File "/home/elvira/.virtualenvs/django_py3/lib/python3.5/site-packages/rest_framework/mixins.py", line 19, in create
    serializer = self.get_serializer(data=request.data)
  File "/home/elvira/.virtualenvs/django_py3/lib/python3.5/site-packages/rest_framework/generics.py", line 112, in get_serializer
    return serializer_class(*args, **kwargs)
TypeError: 'module' object is not callable
INFO 2018-09-19 12:26:57,762 basehttp 124 "GET /usernames/Elvira/count/ HTTP/1.1" 200 31
INFO 2018-09-19 12:26:57,762 basehttp 124 "GET /mobiles/13566778899/count/ HTTP/1.1" 200 34
ERROR 2018-09-19 12:26:57,776 basehttp 124 "POST /users/ HTTP/1.1" 500 20297
ERROR 2018-09-19 12:31:14,037 exception 135 Internal Server Error: /users/
Traceback (most recent call last):
  File "/home/elvira/.virtualenvs/django_py3/lib/python3.5/site-packages/django/core/handlers/exception.py", line 41, in inner
    response = get_response(request)
  File "/home/elvira/.virtualenvs/django_py3/lib/python3.5/site-packages/django/core/handlers/base.py", line 217, in _get_response
    response = self.process_exception_by_middleware(e, request)
  File "/home/elvira/.virtualenvs/django_py3/lib/python3.5/site-packages/django/core/handlers/base.py", line 215, in _get_response
    response = response.render()
  File "/home/elvira/.virtualenvs/django_py3/lib/python3.5/site-packages/django/template/response.py", line 107, in render
    self.content = self.rendered_content
  File "/home/elvira/.virtualenvs/django_py3/lib/python3.5/site-packages/rest_framework/response.py", line 72, in rendered_content
    ret = renderer.render(self.data, accepted_media_type, context)
  File "/home/elvira/.virtualenvs/django_py3/lib/python3.5/site-packages/rest_framework/renderers.py", line 724, in render
    context = self.get_context(data, accepted_media_type, renderer_context)
  File "/home/elvira/.virtualenvs/django_py3/lib/python3.5/site-packages/rest_framework/renderers.py", line 656, in get_context
    raw_data_post_form = self.get_raw_data_form(data, view, 'POST', request)
  File "/home/elvira/.virtualenvs/django_py3/lib/python3.5/site-packages/rest_framework/renderers.py", line 563, in get_raw_data_form
    serializer = view.get_serializer()
  File "/home/elvira/.virtualenvs/django_py3/lib/python3.5/site-packages/rest_framework/generics.py", line 112, in get_serializer
    return serializer_class(*args, **kwargs)
TypeError: 'module' object is not callable
ERROR 2018-09-19 12:31:14,156 basehttp 124 "GET /users/ HTTP/1.1" 500 103351
INFO 2018-09-19 12:32:14,891 basehttp 124 "GET /usernames/Elvira/count/ HTTP/1.1" 200 31
INFO 2018-09-19 12:32:27,804 basehttp 124 "GET /mobiles/13566778899/count/ HTTP/1.1" 200 34
INFO 2018-09-19 12:32:27,955 views 30 短信验证码为: 557775
INFO 2018-09-19 12:32:27,962 basehttp 124 "GET /sms_codes/13566778899/ HTTP/1.1" 200 16
INFO 2018-09-19 12:32:27,968 basehttp 124 "GET /mobiles/13566778899/count/ HTTP/1.1" 200 34
INFO 2018-09-19 12:32:54,276 basehttp 124 "OPTIONS /users/ HTTP/1.1" 200 0
ERROR 2018-09-19 12:32:54,283 exception 135 Internal Server Error: /users/
Traceback (most recent call last):
  File "/home/elvira/.virtualenvs/django_py3/lib/python3.5/site-packages/django/core/handlers/exception.py", line 41, in inner
    response = get_response(request)
  File "/home/elvira/.virtualenvs/django_py3/lib/python3.5/site-packages/django/core/handlers/base.py", line 187, in _get_response
    response = self.process_exception_by_middleware(e, request)
  File "/home/elvira/.virtualenvs/django_py3/lib/python3.5/site-packages/django/core/handlers/base.py", line 185, in _get_response
    response = wrapped_callback(request, *callback_args, **callback_kwargs)
  File "/home/elvira/.virtualenvs/django_py3/lib/python3.5/site-packages/django/views/decorators/csrf.py", line 58, in wrapped_view
    return view_func(*args, **kwargs)
  File "/home/elvira/.virtualenvs/django_py3/lib/python3.5/site-packages/django/views/generic/base.py", line 68, in view
    return self.dispatch(request, *args, **kwargs)
  File "/home/elvira/.virtualenvs/django_py3/lib/python3.5/site-packages/rest_framework/views.py", line 483, in dispatch
    response = self.handle_exception(exc)
  File "/home/elvira/.virtualenvs/django_py3/lib/python3.5/site-packages/rest_framework/views.py", line 443, in handle_exception
    self.raise_uncaught_exception(exc)
  File "/home/elvira/.virtualenvs/django_py3/lib/python3.5/site-packages/rest_framework/views.py", line 480, in dispatch
    response = handler(request, *args, **kwargs)
  File "/home/elvira/.virtualenvs/django_py3/lib/python3.5/site-packages/rest_framework/generics.py", line 192, in post
    return self.create(request, *args, **kwargs)
  File "/home/elvira/.virtualenvs/django_py3/lib/python3.5/site-packages/rest_framework/mixins.py", line 19, in create
    serializer = self.get_serializer(data=request.data)
  File "/home/elvira/.virtualenvs/django_py3/lib/python3.5/site-packages/rest_framework/generics.py", line 112, in get_serializer
    return serializer_class(*args, **kwargs)
TypeError: 'module' object is not callable
INFO 2018-09-19 12:32:54,288 basehttp 124 "GET /usernames/Elvira/count/ HTTP/1.1" 200 31
ERROR 2018-09-19 12:32:54,322 basehttp 124 "POST /users/ HTTP/1.1" 500 20366
INFO 2018-09-19 12:32:54,329 basehttp 124 "GET /mobiles/13566778899/count/ HTTP/1.1" 200 34
ERROR 2018-09-19 12:33:04,132 exception 135 Internal Server Error: /users/
Traceback (most recent call last):
  File "/home/elvira/.virtualenvs/django_py3/lib/python3.5/site-packages/django/core/handlers/exception.py", line 41, in inner
    response = get_response(request)
  File "/home/elvira/.virtualenvs/django_py3/lib/python3.5/site-packages/django/core/handlers/base.py", line 217, in _get_response
    response = self.process_exception_by_middleware(e, request)
  File "/home/elvira/.virtualenvs/django_py3/lib/python3.5/site-packages/django/core/handlers/base.py", line 215, in _get_response
    response = response.render()
  File "/home/elvira/.virtualenvs/django_py3/lib/python3.5/site-packages/django/template/response.py", line 107, in render
    self.content = self.rendered_content
  File "/home/elvira/.virtualenvs/django_py3/lib/python3.5/site-packages/rest_framework/response.py", line 72, in rendered_content
    ret = renderer.render(self.data, accepted_media_type, context)
  File "/home/elvira/.virtualenvs/django_py3/lib/python3.5/site-packages/rest_framework/renderers.py", line 724, in render
    context = self.get_context(data, accepted_media_type, renderer_context)
  File "/home/elvira/.virtualenvs/django_py3/lib/python3.5/site-packages/rest_framework/renderers.py", line 656, in get_context
    raw_data_post_form = self.get_raw_data_form(data, view, 'POST', request)
  File "/home/elvira/.virtualenvs/django_py3/lib/python3.5/site-packages/rest_framework/renderers.py", line 563, in get_raw_data_form
    serializer = view.get_serializer()
  File "/home/elvira/.virtualenvs/django_py3/lib/python3.5/site-packages/rest_framework/generics.py", line 112, in get_serializer
    return serializer_class(*args, **kwargs)
TypeError: 'module' object is not callable
ERROR 2018-09-19 12:33:04,237 basehttp 124 "GET /users/ HTTP/1.1" 500 103351
ERROR 2018-09-19 12:34:20,541 exception 135 Internal Server Error: /users/
Traceback (most recent call last):
  File "/home/elvira/.virtualenvs/django_py3/lib/python3.5/site-packages/django/core/handlers/exception.py", line 41, in inner
    response = get_response(request)
  File "/home/elvira/.virtualenvs/django_py3/lib/python3.5/site-packages/django/core/handlers/base.py", line 217, in _get_response
    response = self.process_exception_by_middleware(e, request)
  File "/home/elvira/.virtualenvs/django_py3/lib/python3.5/site-packages/django/core/handlers/base.py", line 215, in _get_response
    response = response.render()
  File "/home/elvira/.virtualenvs/django_py3/lib/python3.5/site-packages/django/template/response.py", line 107, in render
    self.content = self.rendered_content
  File "/home/elvira/.virtualenvs/django_py3/lib/python3.5/site-packages/rest_framework/response.py", line 72, in rendered_content
    ret = renderer.render(self.data, accepted_media_type, context)
  File "/home/elvira/.virtualenvs/django_py3/lib/python3.5/site-packages/rest_framework/renderers.py", line 724, in render
    context = self.get_context(data, accepted_media_type, renderer_context)
  File "/home/elvira/.virtualenvs/django_py3/lib/python3.5/site-packages/rest_framework/renderers.py", line 656, in get_context
    raw_data_post_form = self.get_raw_data_form(data, view, 'POST', request)
  File "/home/elvira/.virtualenvs/django_py3/lib/python3.5/site-packages/rest_framework/renderers.py", line 563, in get_raw_data_form
    serializer = view.get_serializer()
  File "/home/elvira/.virtualenvs/django_py3/lib/python3.5/site-packages/rest_framework/generics.py", line 112, in get_serializer
    return serializer_class(*args, **kwargs)
TypeError: 'module' object is not callable
ERROR 2018-09-19 12:34:20,636 basehttp 124 "GET /users/ HTTP/1.1" 500 103351
INFO 2018-09-19 12:51:39,559 basehttp 124 "GET /usernames/Elvira/count/ HTTP/1.1" 200 31
INFO 2018-09-19 12:51:48,176 basehttp 124 "GET /mobiles/13566778899/count/ HTTP/1.1" 200 34
INFO 2018-09-19 12:51:48,311 views 30 短信验证码为: 228534
INFO 2018-09-19 12:51:48,318 basehttp 124 "GET /mobiles/13566778899/count/ HTTP/1.1" 200 34
INFO 2018-09-19 12:51:48,365 basehttp 124 "GET /sms_codes/13566778899/ HTTP/1.1" 200 16
INFO 2018-09-19 12:52:00,463 basehttp 124 "OPTIONS /users/ HTTP/1.1" 200 0
ERROR 2018-09-19 12:52:00,466 exception 135 Internal Server Error: /users/
Traceback (most recent call last):
  File "/home/elvira/.virtualenvs/django_py3/lib/python3.5/site-packages/django/core/handlers/exception.py", line 41, in inner
    response = get_response(request)
  File "/home/elvira/.virtualenvs/django_py3/lib/python3.5/site-packages/django/core/handlers/base.py", line 187, in _get_response
    response = self.process_exception_by_middleware(e, request)
  File "/home/elvira/.virtualenvs/django_py3/lib/python3.5/site-packages/django/core/handlers/base.py", line 185, in _get_response
    response = wrapped_callback(request, *callback_args, **callback_kwargs)
  File "/home/elvira/.virtualenvs/django_py3/lib/python3.5/site-packages/django/views/decorators/csrf.py", line 58, in wrapped_view
    return view_func(*args, **kwargs)
  File "/home/elvira/.virtualenvs/django_py3/lib/python3.5/site-packages/django/views/generic/base.py", line 68, in view
    return self.dispatch(request, *args, **kwargs)
  File "/home/elvira/.virtualenvs/django_py3/lib/python3.5/site-packages/rest_framework/views.py", line 483, in dispatch
    response = self.handle_exception(exc)
  File "/home/elvira/.virtualenvs/django_py3/lib/python3.5/site-packages/rest_framework/views.py", line 443, in handle_exception
    self.raise_uncaught_exception(exc)
  File "/home/elvira/.virtualenvs/django_py3/lib/python3.5/site-packages/rest_framework/views.py", line 480, in dispatch
    response = handler(request, *args, **kwargs)
  File "/home/elvira/.virtualenvs/django_py3/lib/python3.5/site-packages/rest_framework/generics.py", line 192, in post
    return self.create(request, *args, **kwargs)
  File "/home/elvira/.virtualenvs/django_py3/lib/python3.5/site-packages/rest_framework/mixins.py", line 19, in create
    serializer = self.get_serializer(data=request.data)
  File "/home/elvira/.virtualenvs/django_py3/lib/python3.5/site-packages/rest_framework/generics.py", line 112, in get_serializer
    return serializer_class(*args, **kwargs)
TypeError: 'module' object is not callable
INFO 2018-09-19 12:52:00,502 basehttp 124 "GET /mobiles/13566778899/count/ HTTP/1.1" 200 34
INFO 2018-09-19 12:52:00,504 basehttp 124 "GET /usernames/Elvira/count/ HTTP/1.1" 200 31
ERROR 2018-09-19 12:52:00,515 basehttp 124 "POST /users/ HTTP/1.1" 500 20309
INFO 2018-09-19 12:57:25,582 basehttp 124 "GET /usernames/Elvira/count/ HTTP/1.1" 200 31
INFO 2018-09-19 12:57:42,136 basehttp 124 "GET /mobiles/13566778899/count/ HTTP/1.1" 200 34
INFO 2018-09-19 12:57:42,294 views 30 短信验证码为: 733606
INFO 2018-09-19 12:57:42,306 basehttp 124 "GET /mobiles/13566778899/count/ HTTP/1.1" 200 34
INFO 2018-09-19 12:57:42,349 basehttp 124 "GET /sms_codes/13566778899/ HTTP/1.1" 200 16
INFO 2018-09-19 12:58:18,384 basehttp 124 "GET /mobiles/13566778899/count/ HTTP/1.1" 200 34
INFO 2018-09-19 12:58:18,385 basehttp 124 "GET /usernames/Elvira/count/ HTTP/1.1" 200 31
INFO 2018-09-19 12:58:18,536 basehttp 124 "POST /users/ HTTP/1.1" 201 225
WARNING 2018-09-19 19:59:02,030 base 152 Not Found: /oauth/qq/authorizations/
WARNING 2018-09-19 19:59:02,031 basehttp 124 "GET /oauth/qq/authorizations/?next=/ HTTP/1.1" 404 2918
WARNING 2018-09-19 19:59:03,438 base 152 Not Found: /oauth/qq/authorizations/
WARNING 2018-09-19 19:59:03,439 basehttp 124 "GET /oauth/qq/authorizations/?next=/ HTTP/1.1" 404 2918
WARNING 2018-09-19 19:59:04,394 base 152 Not Found: /oauth/qq/authorizations/
WARNING 2018-09-19 19:59:04,395 basehttp 124 "GET /oauth/qq/authorizations/?next=/ HTTP/1.1" 404 2918
WARNING 2018-09-19 19:59:05,994 base 152 Not Found: /oauth/qq/authorizations/
WARNING 2018-09-19 19:59:05,995 basehttp 124 "GET /oauth/qq/authorizations/?next=/ HTTP/1.1" 404 2918
WARNING 2018-09-19 19:59:06,416 base 152 Not Found: /oauth/qq/authorizations/
WARNING 2018-09-19 19:59:06,418 basehttp 124 "GET /oauth/qq/authorizations/?next=/ HTTP/1.1" 404 2918
WARNING 2018-09-19 19:59:06,651 base 152 Not Found: /oauth/qq/authorizations/
WARNING 2018-09-19 19:59:06,652 basehttp 124 "GET /oauth/qq/authorizations/?next=/ HTTP/1.1" 404 2918
WARNING 2018-09-19 19:59:06,903 base 152 Not Found: /oauth/qq/authorizations/
WARNING 2018-09-19 19:59:06,904 basehttp 124 "GET /oauth/qq/authorizations/?next=/ HTTP/1.1" 404 2918
WARNING 2018-09-19 19:59:07,319 base 152 Not Found: /oauth/qq/authorizations/
WARNING 2018-09-19 19:59:07,320 basehttp 124 "GET /oauth/qq/authorizations/?next=/ HTTP/1.1" 404 2918
WARNING 2018-09-19 19:59:07,521 base 152 Not Found: /oauth/qq/authorizations/
WARNING 2018-09-19 19:59:07,522 basehttp 124 "GET /oauth/qq/authorizations/?next=/ HTTP/1.1" 404 2918
WARNING 2018-09-19 19:59:08,070 base 152 Not Found: /oauth/qq/authorizations/
WARNING 2018-09-19 19:59:08,071 basehttp 124 "GET /oauth/qq/authorizations/?next=/ HTTP/1.1" 404 2918
WARNING 2018-09-19 19:59:08,290 base 152 Not Found: /oauth/qq/authorizations/
WARNING 2018-09-19 19:59:08,291 basehttp 124 "GET /oauth/qq/authorizations/?next=/ HTTP/1.1" 404 2918
WARNING 2018-09-19 19:59:08,542 base 152 Not Found: /oauth/qq/authorizations/
WARNING 2018-09-19 19:59:08,542 basehttp 124 "GET /oauth/qq/authorizations/?next=/ HTTP/1.1" 404 2918
WARNING 2018-09-19 19:59:08,782 base 152 Not Found: /oauth/qq/authorizations/
WARNING 2018-09-19 19:59:08,783 basehttp 124 "GET /oauth/qq/authorizations/?next=/ HTTP/1.1" 404 2918
WARNING 2018-09-19 20:00:56,834 base 152 Not Found: /oauth/qq/authorizations/
WARNING 2018-09-19 20:00:56,835 basehttp 124 "GET /oauth/qq/authorizations/?next=/ HTTP/1.1" 404 2918
WARNING 2018-09-19 20:02:33,856 base 152 Not Found: /oauth/qq/authorizations/
WARNING 2018-09-19 20:02:33,857 basehttp 124 "GET /oauth/qq/authorizations/?next=/ HTTP/1.1" 404 2918
INFO 2018-09-21 11:21:59,679 basehttp 124 "GET /usernames/Elvira/count/ HTTP/1.1" 200 31
INFO 2018-09-21 11:23:50,896 basehttp 124 "OPTIONS /authorizations/ HTTP/1.1" 200 0
INFO 2018-09-21 11:23:50,943 basehttp 124 "POST /authorizations/ HTTP/1.1" 200 207
WARNING 2018-09-21 11:24:48,810 base 152 Not Found: /oauth/qq/authorizations/
WARNING 2018-09-21 11:24:48,811 basehttp 124 "GET /oauth/qq/authorizations/?next=/ HTTP/1.1" 404 2918
INFO 2018-09-21 11:26:54,477 basehttp 124 "GET /oauth/qq/authorizations/?next=/ HTTP/1.1" 200 195
INFO 2018-09-21 11:27:11,111 basehttp 124 "GET /oauth/qq/user/?code=65FE2BDBA03F6F3631FF71D8CFD3F01E HTTP/1.1" 200 190
INFO 2018-09-21 11:27:25,157 views 30 短信验证码为: 724005
INFO 2018-09-21 11:27:25,288 basehttp 124 "GET /sms_codes/13566778899/ HTTP/1.1" 200 16
INFO 2018-09-21 11:27:44,285 basehttp 124 "OPTIONS /oauth/qq/user/ HTTP/1.1" 200 0
INFO 2018-09-21 11:27:44,430 basehttp 124 "POST /oauth/qq/user/ HTTP/1.1" 201 202
